from pymysql.err import IntegrityError
from models import Model, Field

class Image(Model):

    table_name = "images"

    id = Field(int, modifiable=False)
    user_id = Field(int)
    image64 = Field(str)
    is_primary = Field(bool)
    image_type = Field(str)

    def before_save(self):
        connection = self.pool.get_conn()
        with connection.cursor() as c:
            c.execute("""SELECT COUNT(*) as image_count FROM images WHERE user_id=%s""", (self.user_id))
            result = c.fetchone()
            if result.get("image_count", 0) >= 5 and not self.id:
                self.pool.release(connection)
                raise Exception("Cannot upload image, you already have 5. Please delete an image and reupload.")
        self.pool.release(connection)

    @classmethod
    def check_images(cls, user_id):
        temp = cls()

        connection = temp.pool.get_conn()
        with connection.cursor() as c:
            c.execute("""
              SELECT
                EXISTS(SELECT * FROM images WHERE user_id=%s AND image64!=%s) AS has_images
              from images
            """, (user_id, "&nbsp"))
            temp.pool.release(connection)
            return c.fetchone()
        temp.pool.release(connection)
        return None